<?xml version="1.0"?>
<robot xmlns:xacro="http://www.ros.org/wiki/xacro" name="k_FWD_Robot">



    <xacro:include filename="$(find k_FWD_Robot_description)/urdf/wheel/wheel.gazebo.xacro"/>
    <!-- macro wheel-->
    <xacro:macro name="leg" params="prefix">
        <link name="${prefix}_wheel">
            <inertial>
              <origin xyz="0.0 0.0 0.0" rpy="0.0 0.0 0.0"/>
              <mass value="1.0"/>
              <inertia ixx="0.001" ixy="0.0" ixz="0.0" iyy="0.001" iyz="0.0" izz="0.001"/>
            </inertial>
            <visual name="">
              <origin xyz="0.0 0.0 0.0" rpy="1.5708 0.0 0.0"/>
              <geometry>
                <cylinder radius="0.06" length="0.02"/>
              </geometry>
              <material name="">
                <color rgba="0.0 0.0 0.0 1.0"/>
              </material>
            </visual>
            <collision>
              <geometry>
                <cylinder radius="0.06" length="0.02"/>
              </geometry>
            </collision>
        </link>
    </xacro:macro>




    <xacro:macro name="wheel_v0" params=" prefix parent *joint_origin *joint_axis ">
      <!-- jonts of wheel -->
      <joint name="${prefix}_wheel_joint" type="continuous">
        <xacro:insert_block name="joint_origin"/>
        <parent link="${parent}"/>
        <child link="${prefix}_wheel"/>
        <xacro:insert_block name="joint_axis"/>
        <limit lower="0.0" upper="0.0" effort="0.0" velocity="0.0"/>
      </joint> 
    </xacro:macro>




</robot>